<mujoco model="a1_description">
    <compiler angle="radian" meshdir="../meshes/" />
    <size njmax="500" nconmax="100" />

      <option timestep="0.01" iterations="4" />
  <custom>
    <!-- brax custom params -->
<!--    <numeric data="0.0 0.0 0.55 1.0 0.0 0.0 0.0 0.0 1.0 0.0 -1.0 0.0 -1.0 0.0 1.0" name="init_qpos"/>-->
    <numeric data="0.0 0.0 0.25 1.0 0.0 0.0 0.0   0.0 1.0 -2.0   0.0 1.0 -2.0   0.0 1.0 -2.0   0.0 1.0 -2.0" name="init_qpos"/>
    <numeric data="1000" name="constraint_limit_stiffness"/>
    <numeric data="4000" name="constraint_stiffness"/>
    <numeric data="10" name="constraint_ang_damping"/>
    <numeric data="20" name="constraint_vel_damping"/>
    <numeric data="0.5" name="joint_scale_pos"/>
    <numeric data="0.2" name="joint_scale_ang"/>
    <numeric data="0.0" name="ang_damping"/>
    <numeric data="1" name="spring_mass_scale"/>
    <numeric data="1" name="spring_inertia_scale"/>
    <numeric data="15" name="solver_maxls"/>
  </custom>
    <default>
        <geom contype="1" conaffinity="0" friction="0.6 0.3 0.3" rgba="0.5 0.6 0.7 1" margin="0.001" condim="6" solref="0.02 1" solimp="0.8 0.9 0.01" group="4"/>
        <joint damping="0.01" armature="0.01" frictionloss="0.2" solreflimit="0.01 1" solimplimit="0.9 0.99 0.01" />
    </default>

    <asset>
        <mesh name="trunk" file="trunk.stl" />
        <mesh name="hip" file="hip.stl" />
        <mesh name="thigh_mirror" file="thigh_mirror.stl" />
        <mesh name="calf" file="calf.stl" />
        <mesh name="thigh" file="thigh.stl" />
        <texture builtin="gradient" height="100" rgb1="1 1 1" rgb2="0 0 0" type="skybox" width="100"/>
        <texture builtin="flat" height="1278" mark="cross" markrgb="1 1 1" name="texgeom" random="0.01" rgb1="0.8 0.6 0.4" rgb2="0.8 0.6 0.4" type="cube" width="127"/>

        <texture builtin="checker" height="100" name="texplane" rgb1="0 0 0" rgb2="0.8 0.8 0.8" type="2d" width="100"/>
        <material name="MatPlane" reflectance="0.5" shininess="1" specular="1" texrepeat="60 60" texture="texplane"/>
        <material name="geom" texture="texgeom" texuniform="true"/>
    </asset>

    <worldbody>
        <light cutoff="100" diffuse="1 1 1" dir="-0 0 -1.3" directional="true" exponent="1" pos="0 0 1.3" specular=".1 .1 .1"/>
        <geom conaffinity="0"  density="5.0" friction="1 0.5 0.5" condim="3" material="MatPlane" name="floor" pos="0 0 0" size="40 40 40" type="plane"/>
        <body name="trunk" pos="0 0 0.3">
            <!-- <inertial pos="0.0127283 0.00218554 0.000514891" quat="0.00186575 0.711506 0.000389649 0.702677" mass="4.714" diaginertia="0.0648213 0.0565803 0.0169323" /> -->
            <geom type="mesh" contype="0" conaffinity="0" group="1" rgba="0.913725 0.913725 0.847059 1" mesh="trunk" />
            <geom size="0.1335 0.066 0.057" type="box" rgba="0.913725 0.913725 0.847059 0" />
            <geom size="0.0005 0.0005 0.0005" type="box" contype="0" conaffinity="0" group="1" rgba="0.8 0 0 0" />
            <geom size="0.0005 0.0005 0.0005" type="box" rgba="0.8 0 0 0" />
            <site name="imu" pos="0 0 0"/>
            <joint armature="0" damping="0" limited="false" margin="0.01" name="root" pos="0 0 0" type="free"/>

            <body name="FR_hip" pos="0.183 -0.047 0">
                <!-- <inertial pos="-0.003311 -0.000635 3.1e-05" quat="0.507528 0.506268 0.491507 0.494499" mass="0.696" diaginertia="0.000807752 0.00055293 0.000468983" /> -->
                <joint name="FR_hip_joint" pos="0 0 0" axis="1 0 0" limited="true" range="-0.802851 0.802851" />
                <geom quat="0 1 0 0" type="mesh" contype="0" conaffinity="0" group="1" rgba="0.913725 0.913725 0.847059 1" mesh="hip" />
                <geom size="0.04 0.04" pos="0 -0.055 0" quat="0.707107 0.707107 0 0" type="cylinder" rgba="0.913725 0.913725 0.847059 0" />
                <body name="FR_thigh" pos="0 -0.08505 0">
                    <!-- <inertial pos="-0.003237 0.022327 -0.027326" quat="0.999125 -0.00256393 -0.0409531 -0.00806091" mass="1.013" diaginertia="0.00555739 0.00513936 0.00133944" /> -->
                    <joint name="FR_thigh_joint" pos="0 0 0" axis="0 1 0" limited="true" range="-1.0472 4.18879" />
                    <geom type="mesh" contype="0" conaffinity="0" group="1" rgba="0.913725 0.913725 0.847059 1" mesh="thigh_mirror" />
                    <geom size="0.1 0.01225 0.017" pos="0 0 -0.1" quat="0.707107 0 0.707107 0" type="box" rgba="0.913725 0.913725 0.847059 0" />
                    <body name="FR_calf" pos="0 0 -0.2">
                        <!-- <inertial pos="0.00472659 0 -0.131975" quat="0.706886 0.017653 0.017653 0.706886" mass="0.226" diaginertia="0.00340344 0.00339393 3.54834e-05" /> -->
                        <joint name="FR_calf_joint" pos="0 0 0" axis="0 1 0" limited="true" range="-2.69653 -0.916298" />
                        <geom type="mesh" contype="0" conaffinity="0" group="1" rgba="0 0 0 1" mesh="calf" />
                        <geom size="0.1 0.008 0.008" pos="0 0 -0.1" quat="0.707107 0 0.707107 0" type="box" rgba="0 0 0 0" />
                        <geom size="0.01" pos="0 0 -0.2" contype="0" conaffinity="0" group="1" rgba="0 0 0 1" />
                        <geom size="0.02" pos="0 0 -0.2" rgba="0 0 0 1" />
                    </body>
                </body>
            </body>
            <body name="FL_hip" pos="0.183 0.047 0">
                <!-- <inertial pos="-0.003311 0.000635 3.1e-05" quat="0.494499 0.491507 0.506268 0.507528" mass="0.696" diaginertia="0.000807752 0.00055293 0.000468983" /> -->
                <joint name="FL_hip_joint" pos="0 0 0" axis="1 0 0" limited="true" range="-0.802851 0.802851" />
                <geom type="mesh" contype="0" conaffinity="0" group="1" rgba="0.913725 0.913725 0.847059 1" mesh="hip" />
                <geom size="0.04 0.04" pos="0 0.055 0" quat="0.707107 0.707107 0 0" type="cylinder" rgba="0.913725 0.913725 0.847059 0" />
                <body name="FL_thigh" pos="0 0.08505 0">
                    <!-- <inertial pos="-0.003237 -0.022327 -0.027326" quat="0.999125 0.00256393 -0.0409531 0.00806091" mass="1.013" diaginertia="0.00555739 0.00513936 0.00133944" /> -->
                    <joint name="FL_thigh_joint" pos="0 0 0" axis="0 1 0" limited="true" range="-1.0472 4.18879" />
                    <geom type="mesh" contype="0" conaffinity="0" group="1" rgba="0.913725 0.913725 0.847059 1" mesh="thigh" />
                    <geom size="0.1 0.01225 0.017" pos="0 0 -0.1" quat="0.707107 0 0.707107 0" type="box" rgba="0.913725 0.913725 0.847059 0" />
                    <body name="FL_calf" pos="0 0 -0.2">
                        <!-- <inertial pos="0.00472659 0 -0.131975" quat="0.706886 0.017653 0.017653 0.706886" mass="0.226" diaginertia="0.00340344 0.00339393 3.54834e-05" /> -->
                        <joint name="FL_calf_joint" pos="0 0 0" axis="0 1 0" limited="true" range="-2.69653 -0.916298" />
                        <geom type="mesh" contype="0" conaffinity="0" group="1" rgba="0 0 0 1" mesh="calf" />
                        <geom size="0.1 0.008 0.008" pos="0 0 -0.1" quat="0.707107 0 0.707107 0" type="box" rgba="0 0 0 0" />
                        <geom size="0.01" pos="0 0 -0.2" contype="0" conaffinity="0" group="1" rgba="0 0 0 1" />
                        <geom size="0.02" pos="0 0 -0.2" rgba="0 0 0 1" />
                    </body>
                </body>
            </body>
            <body name="RR_hip" pos="-0.183 -0.047 0">
                <!-- <inertial pos="0.003311 -0.000635 3.1e-05" quat="0.491507 0.494499 0.507528 0.506268" mass="0.696" diaginertia="0.000807752 0.00055293 0.000468983" /> -->
                <joint name="RR_hip_joint" pos="0 0 0" axis="1 0 0" limited="true" range="-0.802851 0.802851" />
                <geom quat="0 0 0 -1" type="mesh" contype="0" conaffinity="0" group="1" rgba="0.913725 0.913725 0.847059 1" mesh="hip" />
                <geom size="0.04 0.04" pos="0 -0.055 0" quat="0.707107 0.707107 0 0" type="cylinder" rgba="0.913725 0.913725 0.847059 0" />
                <body name="RR_thigh" pos="0 -0.08505 0">
                    <!-- <inertial pos="-0.003237 0.022327 -0.027326" quat="0.999125 -0.00256393 -0.0409531 -0.00806091" mass="1.013" diaginertia="0.00555739 0.00513936 0.00133944" /> -->
                    <joint name="RR_thigh_joint" pos="0 0 0" axis="0 1 0" limited="true" range="-1.0472 4.18879" />
                    <geom type="mesh" contype="0" conaffinity="0" group="1" rgba="0.913725 0.913725 0.847059 1" mesh="thigh_mirror" />
                    <geom size="0.1 0.01225 0.017" pos="0 0 -0.1" quat="0.707107 0 0.707107 0" type="box" rgba="0.913725 0.913725 0.847059 0" />
                    <body name="RR_calf" pos="0 0 -0.2">
                        <inertial pos="0.00472659 0 -0.131975" quat="0.706886 0.017653 0.017653 0.706886" mass="0.226" diaginertia="0.00340344 0.00339393 3.54834e-05" />
                        <joint name="RR_calf_joint" pos="0 0 0" axis="0 1 0" limited="true" range="-2.69653 -0.916298" />
                        <geom type="mesh" contype="0" conaffinity="0" group="1" rgba="0 0 0 1" mesh="calf" />
                        <geom size="0.1 0.008 0.008" pos="0 0 -0.1" quat="0.707107 0 0.707107 0" type="box" rgba="0 0 0 0" />
                        <geom size="0.01" pos="0 0 -0.2" contype="0" conaffinity="0" group="1" rgba="0 0 0 1" />
                        <geom size="0.02" pos="0 0 -0.2" rgba="0 0 0 1" />
                    </body>
                </body>
            </body>
            <body name="RL_hip" pos="-0.183 0.047 0">
                <!-- <inertial pos="0.003311 0.000635 3.1e-05" quat="0.506268 0.507528 0.494499 0.491507" mass="0.696" diaginertia="0.000807752 0.00055293 0.000468983" /> -->
                <joint name="RL_hip_joint" pos="0 0 0" axis="1 0 0" limited="true" range="-0.802851 0.802851" />
                <geom quat="0 0 1 0" type="mesh" contype="0" conaffinity="0" group="1" rgba="0.913725 0.913725 0.847059 1" mesh="hip" />
                <geom size="0.04 0.04" pos="0 0.055 0" quat="0.707107 0.707107 0 0" type="cylinder" rgba="0.913725 0.913725 0.847059 0" />
                <body name="RL_thigh" pos="0 0.08505 0">
                    <!-- <inertial pos="-0.003237 -0.022327 -0.027326" quat="0.999125 0.00256393 -0.0409531 0.00806091" mass="1.013" diaginertia="0.00555739 0.00513936 0.00133944" /> -->
                    <joint name="RL_thigh_joint" pos="0 0 0" axis="0 1 0" limited="true" range="-1.0472 4.18879" />
                    <geom type="mesh" contype="0" conaffinity="0" group="1" rgba="0.913725 0.913725 0.847059 1" mesh="thigh" />
                    <geom size="0.1 0.01225 0.017" pos="0 0 -0.1" quat="0.707107 0 0.707107 0" type="box" rgba="0.913725 0.913725 0.847059 0" />
                    <body name="RL_calf" pos="0 0 -0.2">
                        <!-- <inertial pos="0.00472659 0 -0.131975" quat="0.706886 0.017653 0.017653 0.706886" mass="0.226" diaginertia="0.00340344 0.00339393 3.54834e-05" /> -->
                        <joint name="RL_calf_joint" pos="0 0 0" axis="0 1 0" limited="true" range="-2.69653 -0.916298" />
                        <geom type="mesh" contype="0" conaffinity="0" group="1" rgba="0 0 0 1" mesh="calf" />
                        <geom size="0.1 0.008 0.008" pos="0 0 -0.1" quat="0.707107 0 0.707107 0" type="box" rgba="0 0 0 0" />
                        <geom size="0.01" pos="0 0 -0.2" contype="0" conaffinity="0" group="1" rgba="0 0 0 1" />
                        <geom size="0.02" pos="0 0 -0.2" rgba="0 0 0 1" />
                    </body>
                </body>
            </body>
        </body>
    </worldbody>

    <actuator>
        <motor name="FR_hip"    gear="1" joint="FR_hip_joint"   ctrllimited="true" ctrlrange="-1.0 1.0"/>
        <motor name="FR_thigh"  gear="1" joint="FR_thigh_joint" ctrllimited="true" ctrlrange="-1.0 1.0"/>
        <motor name="FR_calf"   gear="1" joint="FR_calf_joint"  ctrllimited="true" ctrlrange="-1.0 1.0"/>
        <motor name="FL_hip"    gear="1" joint="FL_hip_joint"   ctrllimited="true" ctrlrange="-1.0 1.0"/>
        <motor name="FL_thigh"  gear="1" joint="FL_thigh_joint" ctrllimited="true" ctrlrange="-1.0 1.0"/>
        <motor name="FL_calf"   gear="1" joint="FL_calf_joint"  ctrllimited="true" ctrlrange="-1.0 1.0"/>
        <motor name="RR_hip"    gear="1" joint="RR_hip_joint"   ctrllimited="true" ctrlrange="-1.0 1.0"/>
        <motor name="RR_thigh"  gear="1" joint="RR_thigh_joint" ctrllimited="true" ctrlrange="-1.0 1.0"/>
        <motor name="RR_calf"   gear="1" joint="RR_calf_joint"  ctrllimited="true" ctrlrange="-1.0 1.0"/>
        <motor name="RL_hip"    gear="1" joint="RL_hip_joint"   ctrllimited="true" ctrlrange="-1.0 1.0"/>
        <motor name="RL_thigh"  gear="1" joint="RL_thigh_joint" ctrllimited="true" ctrlrange="-1.0 1.0"/>
        <motor name="RL_calf"   gear="1" joint="RL_calf_joint"  ctrllimited="true" ctrlrange="-1.0 1.0"/>
    </actuator>

    <sensor>
        <accelerometer name="accelerometer" site="imu"/>
        <gyro name="sensor_gyro" site="imu"/>
        <velocimeter name="velocimeter" site="imu"/>
        <framequat name="framequat" objtype='site' objname="imu"/>
    </sensor>
</mujoco>